INFO 2025-10-04 19:57:57,810 cli 1 137760916282240 Starting server at tcp:port=8000:interface=0.0.0.0
INFO 2025-10-04 19:57:57,813 server 1 137760916282240 HTTP/2 support not enabled (install the http2 and tls Twisted extras)
INFO 2025-10-04 19:57:57,815 server 1 137760916282240 Configuring endpoint tcp:port=8000:interface=0.0.0.0
INFO 2025-10-04 19:57:57,817 server 1 137760916282240 Listening on TCP address 0.0.0.0:8000
ERROR 2025-10-04 20:06:26,138 log 1 137760806528704 Invalid HTTP_HOST header: 'client.localhost'. You may need to add 'client.localhost' to ALLOWED_HOSTS.
Traceback (most recent call last):
  File "/usr/local/lib/python3.11/site-packages/asgiref/sync.py", line 489, in thread_handler
    raise exc_info[1]
  File "/usr/local/lib/python3.11/site-packages/django/core/handlers/exception.py", line 42, in inner
    response = await get_response(request)
               ^^^^^^^^^^^^^^^^^^^^^^^^^^^
  File "/usr/local/lib/python3.11/site-packages/django/utils/deprecation.py", line 132, in __acall__
    response = await sync_to_async(
               ^^^^^^^^^^^^^^^^^^^^
  File "/usr/local/lib/python3.11/site-packages/asgiref/sync.py", line 439, in __call__
    ret = await asyncio.shield(exec_coro)
          ^^^^^^^^^^^^^^^^^^^^^^^^^^^^^^^
  File "/usr/local/lib/python3.11/concurrent/futures/thread.py", line 58, in run
    result = self.fn(*self.args, **self.kwargs)
             ^^^^^^^^^^^^^^^^^^^^^^^^^^^^^^^^^^
  File "/usr/local/lib/python3.11/site-packages/asgiref/sync.py", line 493, in thread_handler
    return func(*args, **kwargs)
           ^^^^^^^^^^^^^^^^^^^^^
  File "/usr/local/lib/python3.11/site-packages/django/middleware/common.py", line 48, in process_request
    host = request.get_host()
           ^^^^^^^^^^^^^^^^^^
  File "/usr/local/lib/python3.11/site-packages/django/http/request.py", line 202, in get_host
    raise DisallowedHost(msg)
django.core.exceptions.DisallowedHost: Invalid HTTP_HOST header: 'client.localhost'. You may need to add 'client.localhost' to ALLOWED_HOSTS.
ERROR 2025-10-04 20:06:26,480 log 1 137760806528704 Invalid HTTP_HOST header: 'client.localhost'. You may need to add 'client.localhost' to ALLOWED_HOSTS.
Traceback (most recent call last):
  File "/usr/local/lib/python3.11/site-packages/asgiref/sync.py", line 489, in thread_handler
    raise exc_info[1]
  File "/usr/local/lib/python3.11/site-packages/django/core/handlers/exception.py", line 42, in inner
    response = await get_response(request)
               ^^^^^^^^^^^^^^^^^^^^^^^^^^^
  File "/usr/local/lib/python3.11/site-packages/django/utils/deprecation.py", line 132, in __acall__
    response = await sync_to_async(
               ^^^^^^^^^^^^^^^^^^^^
  File "/usr/local/lib/python3.11/site-packages/asgiref/sync.py", line 439, in __call__
    ret = await asyncio.shield(exec_coro)
          ^^^^^^^^^^^^^^^^^^^^^^^^^^^^^^^
  File "/usr/local/lib/python3.11/concurrent/futures/thread.py", line 58, in run
    result = self.fn(*self.args, **self.kwargs)
             ^^^^^^^^^^^^^^^^^^^^^^^^^^^^^^^^^^
  File "/usr/local/lib/python3.11/site-packages/asgiref/sync.py", line 493, in thread_handler
    return func(*args, **kwargs)
           ^^^^^^^^^^^^^^^^^^^^^
  File "/usr/local/lib/python3.11/site-packages/django/middleware/common.py", line 48, in process_request
    host = request.get_host()
           ^^^^^^^^^^^^^^^^^^
  File "/usr/local/lib/python3.11/site-packages/django/http/request.py", line 202, in get_host
    raise DisallowedHost(msg)
django.core.exceptions.DisallowedHost: Invalid HTTP_HOST header: 'client.localhost'. You may need to add 'client.localhost' to ALLOWED_HOSTS.
INFO 2025-10-13 02:47:38,379 autoreload 1241 134839531395968 Watching for file changes with StatReloader
